<?xml version="1.0" ?>
<!-- =================================================================================== -->
<!-- |    This document was autogenerated by xacro from vito_iliad.urdf.xacro          | -->
<!-- |    EDITING THIS FILE BY HAND IS NOT RECOMMENDED                                 | -->
<!-- =================================================================================== -->
<robot name="vito" xmlns:controller="http://playerstage.sourceforge.net/gazebo/xmlschema/#controller" xmlns:interface="http://playerstage.sourceforge.net/gazebo/xmlschema/#interface" xmlns:sensor="http://playerstage.sourceforge.net/gazebo/xmlschema/#sensor" xmlns:xacro="http://www.ros.org/wiki/xacro">
  <material name="Vito/DarkGrey">
    <color rgba="0.3 0.3 0.3 1.0"/>
  </material>
  <material name="Vito/LightGrey">
    <color rgba="0.8 0.8 0.8 1.0"/>
  </material>
  <material name="Vito/Red">
    <color rgba="0.3 0.3 0.3 1.0"/>
  </material>
  <material name="Vito/Black">
    <color rgba="0 0 0 1.0"/>
  </material>
  <material name="Vito/Orange">
    <color rgba="1.0 0.487 0 1.0"/>
  </material>
  <material name="Vito/Silver">
    <color rgba="1.0 1.0 1.0 1.0"/>
  </material>
  <material name="Vito/Grey">
    <color rgba="0.7 0.7 0.7 1.0"/>
  </material>
  <material name="Vito/Blue">
    <color rgba="0.0 0.0 0.8 1.0"/>
  </material>
  <material name="Vito/HandGray">
    <color rgba="0.953 0.996 0.694 1.0"/>
  </material>
  <material name="Vito/SickBlue">
    <color rgba="0.3058 0.5921 0.7294 1.0"/>
  </material>
  <material name="Kuka/DarkGrey">
    <color rgba="0.3 0.3 0.3 1.0"/>
  </material>
  <material name="Kuka/LightGrey">
    <color rgba="0.8 0.8 0.8 1.0"/>
  </material>
  <material name="Kuka/Red">
    <color rgba="0.3 0.3 0.3 1.0"/>
  </material>
  <material name="Kuka/Black">
    <color rgba="0 0 0 1.0"/>
  </material>
  <material name="Kuka/Orange">
    <color rgba="1.0 0.487 0 1.0"/>
  </material>
  <material name="Kuka/Silver">
    <color rgba="1.0 1.0 1.0 1.0"/>
  </material>
  <material name="Kuka/Grey">
    <color rgba="0.7 0.7 0.7 1.0"/>
  </material>
  <material name="Kuka/Blue">
    <color rgba="0.0 0.0 0.8 1.0"/>
  </material>
  <!-- reflex to stiffness -->
  <!-- reflex to damping -->
  <!-- reflex to additional torque -->
  <material name="SoftHand/LightGrey">
    <color rgba="0.7 0.7 0.7 1.0"/>
  </material>
  <material name="SoftHand/DarkGrey">
    <color rgba="0.4 0.4 0.4 1.0"/>
  </material>
  <material name="SoftHand/Black">
    <color rgba="0.0 0.0 0.0 1.0"/>
  </material>
  <material name="SoftHand/DarkGolden">
    <color rgba="0.4 0.4 0.3 1.0"/>
  </material>
  <material name="SoftHand/Blue">
    <color rgba="0.0 0.0 0.8 0.9"/>
  </material>
  <material name="SoftHand/LightBlue">
    <color rgba="0.0 0.4 1.0 0.5"/>
  </material>
  <!-- <xacro:insert_block name="gazebo_friction_properties"/> -->
  <!-- <xacro:insert_block name="gazebo_other_properties"/> -->
  <!-- NOTE: inertia values are approximated using meshlab and only using the significant elements -->
  <!-- from http://answers.ros.org/question/11350/is-there-any-way-to-calculate-inertial-property-of-a-robot-to-simulate-it-in-gazebo/s
    One general rule of thumb I use for checking my inertia tensors is: If total mass of the rigid body is m, and the dimension of the corresponding body is d, then check to see if ixx, iyy, izz are near m*(d/2)^2.

    This is by no means correct, but a sanity check to make sure the moment of inertia are the right order of magnitudes, so the model behaves somewhat physically realistically.
    -->
  <link name="world"/>
  <link name="vito_anchor"/>
  <joint name="w_fixed" type="fixed">
    <origin rpy="0 0 0" xyz="0.0 0.0 0.0"/>
    <!-- <origin xyz="0.0 0.0 0.0" rpy="0 0 0"/> -->
    <parent link="world"/>
    <child link="vito_anchor"/>
  </joint>
  <!-- BODY -->
  <!--  <xacro:model_table name="table" 
                    parent="world"
                    length="0.725"
                    width="1.05"
                    height="0.910"
                    plate_thickness="0.05">
    <origin xyz="-0.215 0.55 0" rpy="0 0 0"/>
  </xacro:model_table>
 -->
  <!--xacro:model_table name="workbench"
                    parent="world"
                    length="0.725"
                    width="1.25"
                    height="0.910"
                    plate_thickness="0.05">
  <origin xyz="-1.25 0.625 0.00" rpy="0 0 0"/>
  </xacro:model_table-->
  <!--     <joint name="camera_kuka_base_joint" type="fixed">
      <origin xyz="0.104 -0.056 0.097" rpy="-0.035 0.002 1.555"/>
      <parent link="right_arm_7_link"/>
      <child link="camera_rgb_optical_frame"/>
    </joint> -->
  <!--        <joint name="camera_kuka_base_joint" type="fixed">
      <origin xyz="0.067 -0.056 0.101" rpy="-2.584 -1.543 -0.572"/>
      <parent link="right_arm_7_link"/>
      <child link="camera_link"/>
    </joint> -->
  <!--    <xacro:asus_xtion_camera name="camera_rviz" parent="camera_rgb_optical_frame" tilt="0"> 
 -->
  <!-- <origin xyz="-0.1650   -0.0000    0.3814" rpy="-2.1588   -0.4478    1.8518"/> -->
  <!--     <origin xyz="0.01 0.037 0" rpy="1.5708 -1.5708 0"/>      
 -->
  <!-- <origin xyz="0.00 0.00 -0.037" rpy="0 0 0"/>       -->
  <!-- <origin xyz="0.57 0.801 1.407" rpy="3.1415 0.5235987010713441 3.1415"/> -->
  <!-- conf inverse kinematic -->
  <!--   </xacro:asus_xtion_camera> 
 -->
  <!-- TORSO -->
  <!-- <xacro:model_torso name="torso" parent="world">
    <origin xyz="0 0 0.0" rpy="0 0 0"/>
  </xacro:model_torso> -->
  <!-- First (shoulder) element of the arm. Fixed to its parent. -->
  <joint name="vito_anchor_left_arm_base_joint" type="fixed">
    <origin rpy="3.1415 0.5235987010713441 3.1415" xyz="0.57 0.801 1.307"/>
    <origin rpy="0 0 0" xyz="0 0 0"/>
    <parent link="vito_anchor"/>
    <child link="left_arm_base_link"/>
  </joint>
  <link name="left_arm_base_link">
    <inertial>
      <mass value="2.0"/>
      <origin xyz="0 0 0.055"/>
      <inertia ixx="0.00381666666667" ixy="0" ixz="0" iyy="0.0036" iyz="0" izz="0.00381666666667"/>
    </inertial>
    <visual>
      <origin rpy="0 0 3.14159265" xyz="0 0 0"/>
      <geometry>
        <mesh filename="meshes/lwr4plus/visual/base.STL"/>
      </geometry>
      <material name="Kuka/Orange"/>
    </visual>
    <collision>
      <origin rpy="0 0 3.14159265" xyz="0 0 0.055"/>
      <geometry>
        <cylinder length="0.11" radius="0.07"/>
      </geometry>
    </collision>
  </link>
  <!-- Second segment of the arm. Joint along z-axis -->
  <joint name="left_arm_a1_joint" type="revolute">
    <origin rpy="0 0 0" xyz="0 0 0.11"/>
    <axis xyz="0 0 1"/>
    <limit effort="176" lower="-2.967059725" upper="2.967059725" velocity="1.919862175"/>
    <dynamics damping="0.7" friction="1.0"/>
    <parent link="left_arm_base_link"/>
    <child link="left_arm_1_link"/>
  </joint>
  <link name="left_arm_1_link">
    <inertial>
      <mass value="2.35"/>
      <origin rpy="0 0 0" xyz="0.00000301 0.02391176 0.11939403"/>
      <inertia ixx="0.013693809375" ixy="4.968005e-07" ixz="8.730822e-07" iyy="0.01353901875" iyz="-0.002371578125" izz="0.004089665625"/>
    </inertial>
    <visual>
      <origin rpy="0 0 3.14159265" xyz="0 0 -0.008"/>
      <geometry>
        <mesh filename="meshes/lwr4plus/visual/link_1.STL"/>
      </geometry>
      <material name="Kuka/Orange"/>
    </visual>
    <collision>
      <origin rpy="0 0 0" xyz="0 0 0.0"/>
      <geometry>
        <sphere radius="0.07"/>
      </geometry>
    </collision>
    <collision>
      <origin rpy="0 0 0" xyz="0 0.06 0.2"/>
      <geometry>
        <sphere radius="0.07"/>
      </geometry>
    </collision>
    <collision>
      <origin rpy="-0.291 0 0" xyz="0 0.03 0.1"/>
      <geometry>
        <cylinder length="0.208" radius="0.07"/>
      </geometry>
    </collision>
  </link>
  <!-- Third segment of the arm. Joint along y-axis -->
  <joint name="left_arm_a2_joint" type="revolute">
    <origin rpy="0 0 0" xyz="0 0 0.2005"/>
    <axis xyz="0 -1 0"/>
    <limit effort="176" lower="-2.0943951" upper="2.0943951" velocity="1.919862175"/>
    <dynamics damping="0.7" friction="1.0"/>
    <parent link="left_arm_1_link"/>
    <child link="left_arm_2_link"/>
  </joint>
  <link name="left_arm_2_link">
    <inertial>
      <mass value="2.35"/>
      <origin rpy="0 0 0" xyz="0.00000301 -0.02391175 0.08110597"/>
      <inertia ixx="0.013693809375" ixy="-4.968005e-07" ixz="-8.730822e-07" iyy="0.01353901875" iyz="-0.002371578125" izz="0.004089665625"/>
    </inertial>
    <visual>
      <origin rpy="0 0 3.14159265" xyz="0 0 0.0"/>
      <geometry>
        <mesh filename="meshes/lwr4plus/visual/link_2.STL"/>
      </geometry>
      <material name="Kuka/Orange"/>
    </visual>
    <collision>
      <origin rpy="0 0 0" xyz="0 0 0.2"/>
      <geometry>
        <sphere radius="0.07"/>
      </geometry>
    </collision>
    <collision>
      <origin rpy="0 0 0" xyz="0 -0.06 0.0"/>
      <geometry>
        <sphere radius="0.07"/>
      </geometry>
    </collision>
    <collision>
      <origin rpy="-0.291 0 0" xyz="0 -0.03 0.1"/>
      <geometry>
        <cylinder length="0.208" radius="0.07"/>
      </geometry>
    </collision>
  </link>
  <!-- Fourth element of the arm. z-axis -->
  <joint name="left_arm_e1_joint" type="revolute">
    <origin rpy="0 0 0" xyz="0 0 0.20"/>
    <axis xyz="0 0 1"/>
    <limit effort="100" lower="-2.967059725" upper="2.967059725" velocity="2.23402144"/>
    <dynamics damping="0.7" friction="1.0"/>
    <parent link="left_arm_2_link"/>
    <child link="left_arm_3_link"/>
  </joint>
  <link name="left_arm_3_link">
    <inertial>
      <mass value="2.35"/>
      <origin rpy="0 0 0" xyz="-0.00000302 -.02391175 0.11939403"/>
      <inertia ixx="0.013693809375" ixy="4.968005e-07" ixz="-8.730822e-07" iyy="0.01353901875" iyz="0.002371578125" izz="0.004089665625"/>
    </inertial>
    <visual>
      <origin rpy="0 0 3.14159265" xyz="0 0 -0.008"/>
      <geometry>
        <mesh filename="meshes/lwr4plus/visual/link_3.STL"/>
      </geometry>
      <material name="Kuka/Orange"/>
    </visual>
    <collision>
      <origin rpy="0 0 0" xyz="0 0 0.0"/>
      <geometry>
        <sphere radius="0.07"/>
      </geometry>
    </collision>
    <collision>
      <origin rpy="0 0 0" xyz="0 -0.06 0.2"/>
      <geometry>
        <sphere radius="0.07"/>
      </geometry>
    </collision>
    <collision>
      <origin rpy="0.291 0 0" xyz="0 -0.03 0.1"/>
      <geometry>
        <cylinder length="0.208" radius="0.07"/>
      </geometry>
    </collision>
  </link>
  <!-- fifth element of the arm. x-axis -->
  <joint name="left_arm_a3_joint" type="revolute">
    <origin rpy="0 0 0" xyz="0 0 0.20"/>
    <axis xyz="0 1 0"/>
    <limit effort="100" lower="-2.0943951" upper="2.0943951" velocity="2.23402144"/>
    <dynamics damping="0.7" friction="1.0"/>
    <parent link="left_arm_3_link"/>
    <child link="left_arm_4_link"/>
  </joint>
  <link name="left_arm_4_link">
    <inertial>
      <mass value="2.35"/>
      <origin rpy="0 0 0" xyz="-0.00000303 .02391175 0.08110597"/>
      <inertia ixx="0.013693809375" ixy="-4.968005e-07" ixz="8.730822e-07" iyy="0.01353901875" iyz="0.002371578125" izz="0.004089665625"/>
    </inertial>
    <visual>
      <origin rpy="0 0 3.14159265" xyz="0 0 0.0"/>
      <geometry>
        <mesh filename="meshes/lwr4plus/visual/link_4.STL"/>
      </geometry>
      <material name="Kuka/Orange"/>
    </visual>
    <collision>
      <origin rpy="0 0 0" xyz="0 0 0.2"/>
      <geometry>
        <sphere radius="0.07"/>
      </geometry>
    </collision>
    <collision>
      <origin rpy="0 0 0" xyz="0 0.06 0.0"/>
      <geometry>
        <sphere radius="0.07"/>
      </geometry>
    </collision>
    <collision>
      <origin rpy="0.291 0 0" xyz="0 0.03 0.1"/>
      <geometry>
        <cylinder length="0.208" radius="0.07"/>
      </geometry>
    </collision>
  </link>
  <!-- Sixth element of the arm. z-axis -->
  <joint name="left_arm_a4_joint" type="revolute">
    <origin rpy="0 0 0" xyz="0 0 0.20"/>
    <axis xyz="0 0 1"/>
    <limit effort="100" lower="-2.967059725" upper="2.967059725" velocity="3.56047167"/>
    <dynamics damping="0.7" friction="1.0"/>
    <parent link="left_arm_4_link"/>
    <child link="left_arm_5_link"/>
  </joint>
  <link name="left_arm_5_link">
    <inertial>
      <mass value="2.35"/>
      <origin rpy="0 0 0" xyz="-0.00000303 .02391175 0.08110597"/>
      <inertia ixx="0.0082625953125" ixy="5.603518e-07" ixz="8.553005e-07" iyy="0.007622859375" iyz="-0.0024984386719" izz="0.0033607035156"/>
    </inertial>
    <visual>
      <origin rpy="0 0 3.14159265" xyz="0 0 -0.008"/>
      <geometry name="left_arm_5_geom">
        <mesh filename="meshes/lwr4plus/visual/link_5.STL"/>
      </geometry>
      <material name="Kuka/Orange"/>
    </visual>
    <collision>
      <origin rpy="0 0 0" xyz="0 0 0.0"/>
      <geometry>
        <sphere radius="0.07"/>
      </geometry>
    </collision>
    <collision>
      <origin rpy="0 0 0" xyz="0 0.04 0.19"/>
      <geometry>
        <sphere radius="0.07"/>
      </geometry>
    </collision>
    <collision>
      <origin rpy="-0.207 0 0" xyz="0 0.02 0.095"/>
      <geometry>
        <cylinder length="0.198" radius="0.07"/>
      </geometry>
    </collision>
  </link>
  <!-- Seventh element of the arm. z-axis -->
  <joint name="left_arm_a5_joint" type="revolute">
    <origin rpy="0 0 0" xyz="0 0 0.19"/>
    <axis xyz="0 -1 0"/>
    <limit effort="38" lower="-2.0943951" upper="2.0943951" velocity="3.21140582"/>
    <dynamics damping="0.7" friction="1.0"/>
    <parent link="left_arm_5_link"/>
    <child link="left_arm_6_link"/>
  </joint>
  <link name="left_arm_6_link">
    <inertial>
      <mass value="1.1"/>
      <origin rpy="0 0 0" xyz="-0.00000001 -.00447585 -0.00290105"/>
      <inertia ixx="0.0029610587891" ixy="-2.319e-10" ixz="2.3622e-09" iyy="0.0029691074219" iyz="2.46776962e-05" izz="0.0032060654297"/>
    </inertial>
    <visual>
      <origin rpy="0 0 3.14159265" xyz="0 0 0"/>
      <geometry>
        <mesh filename="meshes/lwr4plus/visual/link_6.STL"/>
      </geometry>
      <material name="Kuka/Grey"/>
    </visual>
    <collision>
      <origin rpy="0 0 3.14159265" xyz="0 -0.01 0"/>
      <geometry>
        <sphere radius="0.08"/>
      </geometry>
    </collision>
  </link>
  <!-- Eighth element of the arm. z-axis -->
  <joint name="left_arm_a6_joint" type="revolute">
    <origin rpy="0 0 0" xyz="0 0 0.078"/>
    <axis xyz="0 0 1"/>
    <limit effort="38" lower="-2.967059725" upper="2.967059725" velocity="3.21140582"/>
    <dynamics damping="0.7" friction="1.0"/>
    <parent link="left_arm_6_link"/>
    <child link="left_arm_7_link"/>
  </joint>
  <link name="left_arm_7_link">
    <inertial>
      <mass value="0.25"/>
      <origin rpy="0 0 0" xyz="0 0 -0.014685"/>
      <!-- <inertia ixx="${414.478149 / inertia_scale}" ixy="0.0" ixz="0.0" iyy="${414.478149 / inertia_scale}" iyz="0.0" izz="${694.374329 / inertia_scale}" /> -->
      <!-- <inertia ixx="${2 * tip_mass * 0.1 * 0.1 / 5}"  ixy="0"  ixz="0" iyy="${2 * tip_mass * 0.1 * 0.1 / 5}" iyz="0" izz="${2 * tip_mass * 0.1 * 0.1 / 5}" /> -->
      <inertia ixx="0.000633333333333" ixy="0" ixz="0" iyy="0.000633333333333" iyz="0" izz="0.000633333333333"/>
    </inertial>
    <visual>
      <origin rpy="0 0 3.14159265" xyz="0 0 0"/>
      <geometry>
        <mesh filename="meshes/lwr4plus/visual/link_7.STL"/>
      </geometry>
      <material name="Kuka/DarkGrey"/>
    </visual>
    <!-- 
			<collision>
			<origin xyz="0 0 -0.005" rpy="0 0 ${M_PI}"/>
			<geometry>
				<cylinder radius="0.04" length="0.01"/>
			</geometry>
			</collision> -->
  </link>
  <!-- LEFT SOFTHAND -->
  <!--  <xacro:soft_hand parent="left_arm_7_link" name="left_hand" left="true" withAdaptiveTransmission="true" useMimicTag="$(arg use_mimic_tag)">
    <origin xyz="0 0 0" rpy="0 0 0"/>
  </xacro:soft_hand> -->
  <!-- First (shoulder) element of the arm. Fixed to its parent. -->
  <joint name="vito_anchor_right_arm_base_joint" type="fixed">
    <origin rpy="3.1415 -0.7854 0" xyz="0.77 0.801 1.607"/>
    <origin rpy="0 0 0" xyz="0 0 0"/>
    <parent link="vito_anchor"/>
    <child link="right_arm_base_link"/>
  </joint>
  <link name="right_arm_base_link">
    <inertial>
      <mass value="2.0"/>
      <origin xyz="0 0 0.055"/>
      <inertia ixx="0.00381666666667" ixy="0" ixz="0" iyy="0.0036" iyz="0" izz="0.00381666666667"/>
    </inertial>
    <visual>
      <origin rpy="0 0 3.14159265" xyz="0 0 0"/>
      <geometry>
        <mesh filename="meshes/lwr4plus/visual/base.STL"/>
      </geometry>
      <material name="Kuka/Orange"/>
    </visual>
    <collision>
      <origin rpy="0 0 3.14159265" xyz="0 0 0.055"/>
      <geometry>
        <cylinder length="0.11" radius="0.07"/>
      </geometry>
    </collision>
  </link>
  <!-- Second segment of the arm. Joint along z-axis -->
  <joint name="right_arm_a1_joint" type="revolute">
    <origin rpy="0 0 0" xyz="0 0 0.11"/>
    <axis xyz="0 0 1"/>
    <limit effort="176" lower="-2.967059725" upper="2.967059725" velocity="1.919862175"/>
    <dynamics damping="0.7" friction="1.0"/>
    <parent link="right_arm_base_link"/>
    <child link="right_arm_1_link"/>
  </joint>
  <link name="right_arm_1_link">
    <inertial>
      <mass value="2.35"/>
      <origin rpy="0 0 0" xyz="0.00000301 0.02391176 0.11939403"/>
      <inertia ixx="0.013693809375" ixy="4.968005e-07" ixz="8.730822e-07" iyy="0.01353901875" iyz="-0.002371578125" izz="0.004089665625"/>
    </inertial>
    <visual>
      <origin rpy="0 0 3.14159265" xyz="0 0 -0.008"/>
      <geometry>
        <mesh filename="meshes/lwr4plus/visual/link_1.STL"/>
      </geometry>
      <material name="Kuka/Orange"/>
    </visual>
    <collision>
      <origin rpy="0 0 0" xyz="0 0 0.0"/>
      <geometry>
        <sphere radius="0.07"/>
      </geometry>
    </collision>
    <collision>
      <origin rpy="0 0 0" xyz="0 0.06 0.2"/>
      <geometry>
        <sphere radius="0.07"/>
      </geometry>
    </collision>
    <collision>
      <origin rpy="-0.291 0 0" xyz="0 0.03 0.1"/>
      <geometry>
        <cylinder length="0.208" radius="0.07"/>
      </geometry>
    </collision>
  </link>
  <!-- Third segment of the arm. Joint along y-axis -->
  <joint name="right_arm_a2_joint" type="revolute">
    <origin rpy="0 0 0" xyz="0 0 0.2005"/>
    <axis xyz="0 -1 0"/>
    <limit effort="176" lower="-2.0943951" upper="2.0943951" velocity="1.919862175"/>
    <dynamics damping="0.7" friction="1.0"/>
    <parent link="right_arm_1_link"/>
    <child link="right_arm_2_link"/>
  </joint>
  <link name="right_arm_2_link">
    <inertial>
      <mass value="2.35"/>
      <origin rpy="0 0 0" xyz="0.00000301 -0.02391175 0.08110597"/>
      <inertia ixx="0.013693809375" ixy="-4.968005e-07" ixz="-8.730822e-07" iyy="0.01353901875" iyz="-0.002371578125" izz="0.004089665625"/>
    </inertial>
    <visual>
      <origin rpy="0 0 3.14159265" xyz="0 0 0.0"/>
      <geometry>
        <mesh filename="meshes/lwr4plus/visual/link_2.STL"/>
      </geometry>
      <material name="Kuka/Orange"/>
    </visual>
    <collision>
      <origin rpy="0 0 0" xyz="0 0 0.2"/>
      <geometry>
        <sphere radius="0.07"/>
      </geometry>
    </collision>
    <collision>
      <origin rpy="0 0 0" xyz="0 -0.06 0.0"/>
      <geometry>
        <sphere radius="0.07"/>
      </geometry>
    </collision>
    <collision>
      <origin rpy="-0.291 0 0" xyz="0 -0.03 0.1"/>
      <geometry>
        <cylinder length="0.208" radius="0.07"/>
      </geometry>
    </collision>
  </link>
  <!-- Fourth element of the arm. z-axis -->
  <joint name="right_arm_e1_joint" type="revolute">
    <origin rpy="0 0 0" xyz="0 0 0.20"/>
    <axis xyz="0 0 1"/>
    <limit effort="100" lower="-2.967059725" upper="2.967059725" velocity="2.23402144"/>
    <dynamics damping="0.7" friction="1.0"/>
    <parent link="right_arm_2_link"/>
    <child link="right_arm_3_link"/>
  </joint>
  <link name="right_arm_3_link">
    <inertial>
      <mass value="2.35"/>
      <origin rpy="0 0 0" xyz="-0.00000302 -.02391175 0.11939403"/>
      <inertia ixx="0.013693809375" ixy="4.968005e-07" ixz="-8.730822e-07" iyy="0.01353901875" iyz="0.002371578125" izz="0.004089665625"/>
    </inertial>
    <visual>
      <origin rpy="0 0 3.14159265" xyz="0 0 -0.008"/>
      <geometry>
        <mesh filename="meshes/lwr4plus/visual/link_3.STL"/>
      </geometry>
      <material name="Kuka/Orange"/>
    </visual>
    <collision>
      <origin rpy="0 0 0" xyz="0 0 0.0"/>
      <geometry>
        <sphere radius="0.07"/>
      </geometry>
    </collision>
    <collision>
      <origin rpy="0 0 0" xyz="0 -0.06 0.2"/>
      <geometry>
        <sphere radius="0.07"/>
      </geometry>
    </collision>
    <collision>
      <origin rpy="0.291 0 0" xyz="0 -0.03 0.1"/>
      <geometry>
        <cylinder length="0.208" radius="0.07"/>
      </geometry>
    </collision>
  </link>
  <!-- fifth element of the arm. x-axis -->
  <joint name="right_arm_a3_joint" type="revolute">
    <origin rpy="0 0 0" xyz="0 0 0.20"/>
    <axis xyz="0 1 0"/>
    <limit effort="100" lower="-2.0943951" upper="2.0943951" velocity="2.23402144"/>
    <dynamics damping="0.7" friction="1.0"/>
    <parent link="right_arm_3_link"/>
    <child link="right_arm_4_link"/>
  </joint>
  <link name="right_arm_4_link">
    <inertial>
      <mass value="2.35"/>
      <origin rpy="0 0 0" xyz="-0.00000303 .02391175 0.08110597"/>
      <inertia ixx="0.013693809375" ixy="-4.968005e-07" ixz="8.730822e-07" iyy="0.01353901875" iyz="0.002371578125" izz="0.004089665625"/>
    </inertial>
    <visual>
      <origin rpy="0 0 3.14159265" xyz="0 0 0.0"/>
      <geometry>
        <mesh filename="meshes/lwr4plus/visual/link_4.STL"/>
      </geometry>
      <material name="Kuka/Orange"/>
    </visual>
    <collision>
      <origin rpy="0 0 0" xyz="0 0 0.2"/>
      <geometry>
        <sphere radius="0.07"/>
      </geometry>
    </collision>
    <collision>
      <origin rpy="0 0 0" xyz="0 0.06 0.0"/>
      <geometry>
        <sphere radius="0.07"/>
      </geometry>
    </collision>
    <collision>
      <origin rpy="0.291 0 0" xyz="0 0.03 0.1"/>
      <geometry>
        <cylinder length="0.208" radius="0.07"/>
      </geometry>
    </collision>
  </link>
  <!-- Sixth element of the arm. z-axis -->
  <joint name="right_arm_a4_joint" type="revolute">
    <origin rpy="0 0 0" xyz="0 0 0.20"/>
    <axis xyz="0 0 1"/>
    <limit effort="100" lower="-2.967059725" upper="2.967059725" velocity="3.56047167"/>
    <dynamics damping="0.7" friction="1.0"/>
    <parent link="right_arm_4_link"/>
    <child link="right_arm_5_link"/>
  </joint>
  <link name="right_arm_5_link">
    <inertial>
      <mass value="2.35"/>
      <origin rpy="0 0 0" xyz="-0.00000303 .02391175 0.08110597"/>
      <inertia ixx="0.0082625953125" ixy="5.603518e-07" ixz="8.553005e-07" iyy="0.007622859375" iyz="-0.0024984386719" izz="0.0033607035156"/>
    </inertial>
    <visual>
      <origin rpy="0 0 3.14159265" xyz="0 0 -0.008"/>
      <geometry name="right_arm_5_geom">
        <mesh filename="meshes/lwr4plus/visual/link_5.STL"/>
      </geometry>
      <material name="Kuka/Orange"/>
    </visual>
    <collision>
      <origin rpy="0 0 0" xyz="0 0 0.0"/>
      <geometry>
        <sphere radius="0.07"/>
      </geometry>
    </collision>
    <collision>
      <origin rpy="0 0 0" xyz="0 0.04 0.19"/>
      <geometry>
        <sphere radius="0.07"/>
      </geometry>
    </collision>
    <collision>
      <origin rpy="-0.207 0 0" xyz="0 0.02 0.095"/>
      <geometry>
        <cylinder length="0.198" radius="0.07"/>
      </geometry>
    </collision>
  </link>
  <!-- Seventh element of the arm. z-axis -->
  <joint name="right_arm_a5_joint" type="revolute">
    <origin rpy="0 0 0" xyz="0 0 0.19"/>
    <axis xyz="0 -1 0"/>
    <limit effort="38" lower="-2.0943951" upper="2.0943951" velocity="3.21140582"/>
    <dynamics damping="0.7" friction="1.0"/>
    <parent link="right_arm_5_link"/>
    <child link="right_arm_6_link"/>
  </joint>
  <link name="right_arm_6_link">
    <inertial>
      <mass value="1.1"/>
      <origin rpy="0 0 0" xyz="-0.00000001 -.00447585 -0.00290105"/>
      <inertia ixx="0.0029610587891" ixy="-2.319e-10" ixz="2.3622e-09" iyy="0.0029691074219" iyz="2.46776962e-05" izz="0.0032060654297"/>
    </inertial>
    <visual>
      <origin rpy="0 0 3.14159265" xyz="0 0 0"/>
      <geometry>
        <mesh filename="meshes/lwr4plus/visual/link_6.STL"/>
      </geometry>
      <material name="Kuka/Grey"/>
    </visual>
    <collision>
      <origin rpy="0 0 3.14159265" xyz="0 -0.01 0"/>
      <geometry>
        <sphere radius="0.08"/>
      </geometry>
    </collision>
  </link>
  <!-- Eighth element of the arm. z-axis -->
  <joint name="right_arm_a6_joint" type="revolute">
    <origin rpy="0 0 0" xyz="0 0 0.078"/>
    <axis xyz="0 0 1"/>
    <limit effort="38" lower="-2.967059725" upper="2.967059725" velocity="3.21140582"/>
    <dynamics damping="0.7" friction="1.0"/>
    <parent link="right_arm_6_link"/>
    <child link="right_arm_7_link"/>
  </joint>
  <link name="right_arm_7_link">
    <inertial>
      <mass value="0.25"/>
      <origin rpy="0 0 0" xyz="0 0 -0.014685"/>
      <!-- <inertia ixx="${414.478149 / inertia_scale}" ixy="0.0" ixz="0.0" iyy="${414.478149 / inertia_scale}" iyz="0.0" izz="${694.374329 / inertia_scale}" /> -->
      <!-- <inertia ixx="${2 * tip_mass * 0.1 * 0.1 / 5}"  ixy="0"  ixz="0" iyy="${2 * tip_mass * 0.1 * 0.1 / 5}" iyz="0" izz="${2 * tip_mass * 0.1 * 0.1 / 5}" /> -->
      <inertia ixx="0.000633333333333" ixy="0" ixz="0" iyy="0.000633333333333" iyz="0" izz="0.000633333333333"/>
    </inertial>
    <visual>
      <origin rpy="0 0 3.14159265" xyz="0 0 0"/>
      <geometry>
        <mesh filename="meshes/lwr4plus/visual/link_7.STL"/>
      </geometry>
      <material name="Kuka/DarkGrey"/>
    </visual>
    <!-- 
			<collision>
			<origin xyz="0 0 -0.005" rpy="0 0 ${M_PI}"/>
			<geometry>
				<cylinder radius="0.04" length="0.01"/>
			</geometry>
			</collision> -->
  </link>
  <!-- PACMAN VERION ALREADY INCLUDES THE COUPLER, CLAMP AND BASE -->
  <joint name="right_arm_7_link_right_hand_kuka_coupler_joint" type="fixed">
    <origin rpy="0 0 3.1415" xyz="0 0 0"/>
    <parent link="right_arm_7_link"/>
    <child link="right_hand_kuka_coupler_bottom"/>
  </joint>
  <link name="right_hand_kuka_coupler_bottom">
    <visual>
      <origin rpy="0 0 0" xyz="0 0 0.0115"/>
      <geometry>
        <!-- mesh filename="soft_hand_description/meshes/accesories/kuka_coupler.stl"/-->
        <cylinder length="0.023" radius="0.033"/>
      </geometry>
      <material name="SoftHand/Blue"/>
    </visual>
    <collision>
      <origin rpy="0 0 0" xyz="0 0 0.031"/>
      <geometry>
        <cylinder length="0.023" radius="0.033"/>
      </geometry>
    </collision>
  </link>
  <joint name="right_arm_7_link_right_hand_kuka_coupler_base_joint" type="fixed">
    <origin rpy="0 0 0" xyz="0 0 0.023"/>
    <parent link="right_hand_kuka_coupler_bottom"/>
    <child link="right_hand_kuka_coupler"/>
  </joint>
  <link name="right_hand_kuka_coupler"/>
  <joint name="right_hand_kuka_coupler_right_hand_clamp_joint" type="fixed">
    <origin rpy="0 0 0" xyz="0 0 0.01"/>
    <parent link="right_hand_kuka_coupler"/>
    <child link="right_hand_clamp"/>
  </joint>
  <link name="right_hand_clamp">
    <visual>
      <origin rpy="0 0 0" xyz="0 0 0"/>
      <geometry>
        <mesh filename="soft_hand_description/meshes/accesories/clamp.stl"/>
      </geometry>
      <material name="SoftHand/Blue"/>
    </visual>
    <collision>
      <origin rpy="0 0 0" xyz="0 0 0"/>
      <geometry>
        <box size="0.066 0.0725 0.0256"/>
      </geometry>
    </collision>
  </link>
  <joint name="right_hand_clamp_right_hand_softhand_base_joint" type="fixed">
    <origin rpy="3.14 0 -1.57" xyz="0.015 0 0.154"/>
    <parent link="right_hand_clamp"/>
    <child link="right_hand_softhand_base"/>
  </joint>
  <link name="right_hand_softhand_base">
    <visual>
      <origin rpy="0 0 0" xyz="0 0 0"/>
      <geometry>
        <mesh filename="soft_hand_description/meshes/CAD_SoftHand_Research_STL.stl" scale="0.001 0.001 0.001"/>
      </geometry>
    </visual>
    <collision>
      <origin rpy="0 0 0" xyz="0 0 0.031"/>
      <geometry>
        <box size="0.066 0.066 0.062"/>
      </geometry>
    </collision>
  </link>

  <joint name="left_arm_7_link_left_velvet_base_joint" type="fixed">
    <origin rpy="-0.5235987010713441 0 0" xyz="0 0.07 0.1432"/>
    <parent link="left_arm_7_link"/>
    <child link="left_velvet_link"/>
  </joint>
  <link name="left_velvet_link">
    <inertial>
      <origin xyz="0 0 0"/>
      <mass value="1.0"/>
      <inertia ixx="0.01" ixy="0.0" ixz="0.0" iyy="0.01" iyz="0.0" izz="0.01"/>
    </inertial>
    <visual>
      <geometry>
        <mesh filename="meshes/gazebo_assieme.stl"/>
      </geometry>
      <material name="Vito/Silver"/>
    </visual>
    <collision>
      <geometry>
        <mesh filename="meshes/gazebo_assieme.stl"/>
      </geometry>
    </collision>
  </link>



</robot>
